Starting .sh file
/var/spool/slurmd/job1742956/slurm_script: line 20: cd: /home/qlh2987/spring2025/genAI/aesthetic_moodboard_generation: No such file or directory
Environment activated. Starting training...
Starting Python training script...
CVAE training script started.
Traceback (most recent call last):
  File "/home/qlh2976/miniconda/envs/moodgen/lib/python3.9/site-packages/pandas/core/indexes/base.py", line 3805, in get_loc
    return self._engine.get_loc(casted_key)
  File "index.pyx", line 167, in pandas._libs.index.IndexEngine.get_loc
  File "index.pyx", line 196, in pandas._libs.index.IndexEngine.get_loc
  File "pandas/_libs/hashtable_class_helper.pxi", line 7081, in pandas._libs.hashtable.PyObjectHashTable.get_item
  File "pandas/_libs/hashtable_class_helper.pxi", line 7089, in pandas._libs.hashtable.PyObjectHashTable.get_item
KeyError: 'mood'

The above exception was the direct cause of the following exception:

Traceback (most recent call last):
  File "/gpfs/home/qlh2976/spring2025/genAI/aesthetic_moodboard_generation/scripts/train_cvae.py", line 65, in <module>
    full_dataset = load_dataset(
  File "/home/qlh2976/spring2025/genAI/aesthetic_moodboard_generation/utils/dataset.py", line 84, in load_dataset
    mood = row['mood']
  File "/home/qlh2976/miniconda/envs/moodgen/lib/python3.9/site-packages/pandas/core/series.py", line 1121, in __getitem__
    return self._get_value(key)
  File "/home/qlh2976/miniconda/envs/moodgen/lib/python3.9/site-packages/pandas/core/series.py", line 1237, in _get_value
    loc = self.index.get_loc(label)
  File "/home/qlh2976/miniconda/envs/moodgen/lib/python3.9/site-packages/pandas/core/indexes/base.py", line 3812, in get_loc
    raise KeyError(key) from err
KeyError: 'mood'
Training complete!
